"Traceback (most recent call last):
  File ""C:\Users\47955\workspace\super-ml-pets\V6.0\sap.py"", line 48, in step
    shp_slot = self.player.shop[shp_idx]
  File ""c:\users\47955\workspace\super-ml-pets\venv\src\sapai\sapai\shop.py"", line 378, in __getitem__
    return self.shop_slots[idx]
IndexError: list index out of range
"
"Traceback (most recent call last):
  File ""C:\Users\47955\workspace\super-ml-pets\V6.0\sap.py"", line 48, in step
    shp_slot = self.player.shop[shp_idx]
  File ""c:\users\47955\workspace\super-ml-pets\venv\src\sapai\sapai\shop.py"", line 378, in __getitem__
    return self.shop_slots[idx]
IndexError: list index out of range
"
"Traceback (most recent call last):
  File ""C:\Users\47955\workspace\super-ml-pets\V6.0\sap.py"", line 71, in step
    self.player.combine(tm2_idx, tm1_idx)
  File ""c:\users\47955\workspace\super-ml-pets\venv\src\sapai\sapai\player.py"", line 16, in store_action
    targets = func(*args,**kwargs)
  File ""c:\users\47955\workspace\super-ml-pets\venv\src\sapai\sapai\player.py"", line 480, in combine
    if not self.team.check_friend(pet1):
  File ""c:\users\47955\workspace\super-ml-pets\venv\src\sapai\sapai\teams.py"", line 167, in check_friend
    raise Exception(""Object of type {} not recognized"".format(type(obj)))
Exception: Object of type <class 'numpy.int64'> not recognized
"
"Traceback (most recent call last):
  File ""C:\Users\47955\workspace\super-ml-pets\V6.0\sap.py"", line 48, in step
    shp_slot = self.player.shop[shp_idx]
  File ""c:\users\47955\workspace\super-ml-pets\venv\src\sapai\sapai\shop.py"", line 378, in __getitem__
    return self.shop_slots[idx]
IndexError: list index out of range
"
"Traceback (most recent call last):
  File ""C:\Users\47955\workspace\super-ml-pets\V6.0\sap.py"", line 48, in step
    shp_slot = self.player.shop[shp_idx]
  File ""c:\users\47955\workspace\super-ml-pets\venv\src\sapai\sapai\shop.py"", line 378, in __getitem__
    return self.shop_slots[idx]
IndexError: list index out of range
"
"Traceback (most recent call last):
  File ""C:\Users\47955\workspace\super-ml-pets\V6.0\sap.py"", line 48, in step
    shp_slot = self.player.shop[shp_idx]
  File ""c:\users\47955\workspace\super-ml-pets\venv\src\sapai\sapai\shop.py"", line 378, in __getitem__
    return self.shop_slots[idx]
IndexError: list index out of range
"
"Traceback (most recent call last):
  File ""C:\Users\47955\workspace\super-ml-pets\V6.0\sap.py"", line 48, in step
    shp_slot = self.player.shop[shp_idx]
  File ""c:\users\47955\workspace\super-ml-pets\venv\src\sapai\sapai\shop.py"", line 378, in __getitem__
    return self.shop_slots[idx]
IndexError: list index out of range
"
"Traceback (most recent call last):
  File ""C:\Users\47955\workspace\super-ml-pets\V6.0\sap.py"", line 56, in step
    self.player.team.move(len(self.player.team)-1, tm_idx)
  File ""c:\users\47955\workspace\super-ml-pets\venv\src\sapai\sapai\teams.py"", line 43, in move
    raise Exception(""Attempted move to a populated position"")
Exception: Attempted move to a populated position
"
"Traceback (most recent call last):
  File ""C:\Users\47955\workspace\super-ml-pets\V6.0\sap.py"", line 48, in step
    shp_slot = self.player.shop[shp_idx]
  File ""c:\users\47955\workspace\super-ml-pets\venv\src\sapai\sapai\shop.py"", line 378, in __getitem__
    return self.shop_slots[idx]
IndexError: list index out of range
"
"Traceback (most recent call last):
  File ""C:\Users\47955\workspace\super-ml-pets\V6.0\sap.py"", line 48, in step
    shp_slot = self.player.shop[shp_idx]
  File ""c:\users\47955\workspace\super-ml-pets\venv\src\sapai\sapai\shop.py"", line 378, in __getitem__
    return self.shop_slots[idx]
IndexError: list index out of range
"
"Traceback (most recent call last):
  File ""C:\Users\47955\workspace\super-ml-pets\V6.0\sap.py"", line 48, in step
    shp_slot = self.player.shop[shp_idx]
  File ""c:\users\47955\workspace\super-ml-pets\venv\src\sapai\sapai\shop.py"", line 378, in __getitem__
    return self.shop_slots[idx]
IndexError: list index out of range
"
"Traceback (most recent call last):
  File ""C:\Users\47955\workspace\super-ml-pets\V6.0\sap.py"", line 48, in step
    shp_slot = self.player.shop[shp_idx]
  File ""c:\users\47955\workspace\super-ml-pets\venv\src\sapai\sapai\shop.py"", line 378, in __getitem__
    return self.shop_slots[idx]
IndexError: list index out of range
"
"Traceback (most recent call last):
  File ""C:\Users\47955\workspace\super-ml-pets\V6.0\sap.py"", line 73, in step
    self.player.team.move(tm1_idx, tm2_idx)
  File ""c:\users\47955\workspace\super-ml-pets\venv\src\sapai\sapai\teams.py"", line 43, in move
    raise Exception(""Attempted move to a populated position"")
Exception: Attempted move to a populated position
"
