"Traceback (most recent call last):
  File ""C:\Users\47955\workspace\super-ml-pets\V6.0\sap.py"", line 48, in step
    shp_slot = self.player.shop[shp_idx]
  File ""c:\users\47955\workspace\super-ml-pets\venv\src\sapai\sapai\shop.py"", line 378, in __getitem__
    return self.shop_slots[idx]
IndexError: list index out of range
"
"Traceback (most recent call last):
  File ""C:\Users\47955\workspace\super-ml-pets\V6.0\sap.py"", line 73, in step
    self.player.team.move(tm1_idx, tm2_idx)
  File ""c:\users\47955\workspace\super-ml-pets\venv\src\sapai\sapai\teams.py"", line 43, in move
    raise Exception(""Attempted move to a populated position"")
Exception: Attempted move to a populated position
"
"Traceback (most recent call last):
  File ""C:\Users\47955\workspace\super-ml-pets\V6.0\sap.py"", line 73, in step
    self.player.team.move(tm1_idx, tm2_idx)
  File ""c:\users\47955\workspace\super-ml-pets\venv\src\sapai\sapai\teams.py"", line 43, in move
    raise Exception(""Attempted move to a populated position"")
Exception: Attempted move to a populated position
"
"Traceback (most recent call last):
  File ""C:\Users\47955\workspace\super-ml-pets\V6.0\sap.py"", line 48, in step
    shp_slot = self.player.shop[shp_idx]
  File ""c:\users\47955\workspace\super-ml-pets\venv\src\sapai\sapai\shop.py"", line 378, in __getitem__
    return self.shop_slots[idx]
IndexError: list index out of range
"
